> [异步](https://developer.mozilla.org/zh-CN/docs/Glossary/Asynchronous)
>
> [如何使用 Promise](https://developer.mozilla.org/zh-CN/docs/Learn/JavaScript/Asynchronous/Promises\)
>
> [Promise](https://developer.mozilla.org/zh-CN/docs/Web/JavaScript/Reference/Global_Objects/Promise)



## 概念

**异步**指两个或两个以上的对象或事件**不**同时存在或发生（或多个相关事物的发生无需等待其前一事物的完成）。

异步任务让出主线程，等待请求结果，当有返回结果时，再重新切换回该异步任务（感觉上异步任务是并行的，实际上是单线程交替执行）。相对地，严格按照指令顺序执行，则为同步。

当有多个异步任务时，因为主线程的切换，不干预的情况下，将产生执行顺序混乱的问题，所以 Javascript 的异步方法，都会和该问题相关。



## 宏任务与微任务

> 待增加

- 一般执行顺序：**同步任务 --> 微任务 --> 宏任务**
- 在执行一个 Promise 对象的时候，当走完`resolve();`之后，就会立刻把 `.then()`里面的代码加入到**微任务队列**当中

### 关于嵌套

在执行宏任务的**过程中**，创建了一个微任务。但是需要**先把当前这个宏任务执行完**，再去**创建并执行**微任务



## Promise

### 三种状态

一个 `Promise` 必然处于以下几种状态之一：

- *待定（pending）*: 初始状态，既没有被兑现，也没有被拒绝。
- *已兑现（fulfilled）*: 意味着操作成功完成。
- *已拒绝（rejected）*: 意味着操作失败。



基本使用

```js
let promise = new Promise((resolve, reject) => {
    console.log('同步代码');
    if (判断为成功) {
        resolve('一个值');
    } else { // 判断为失败
        reject('一个值');
    }
});

promise.then(
        value =>{
            。。。
            return newValue
        },
      	reason =>{
            。。。
            return Promise.resolve('一个值'); // 失败了也要传递成功状态值
        }
    )
	.then( value => {
    	// 即使上面的 then 失败也会执行这里的then
    	// 相当于 .then(value=>{}, undefined)
	    // 所以返回 undefined
	    return Promise.reject('一个值'); // 改为失败状态给下一个 then
	})
	.catch(reason =>{
        // 捕获到错误
        // 内部为 obj.then(undefined, onRejected))
    	// 不管之前的 then 的状态如何，都会走到这里，所以可以统一处理失败的情况
    });
```



### Promise.prototype.then()

> 见基础用法



### Promise.prototype.catch()

> 见基础用法



### Promise.resolve()

> 见基础用法



### Promise.reject()

> 见基础用法



### Promise.all()

返回一个[`Promise`](https://developer.mozilla.org/zh-CN/docs/Web/JavaScript/Reference/Global_Objects/Promise)实例，只要任何一个输入的promise的reject回调执行或者输入不合法的promise就会立即抛出错误，并且reject的是第一个抛出的错误信息

```js
const promise1 = Promise.resolve(3);
const promise2 = 42;
const promise3 = new Promise((resolve, reject) => {
  setTimeout(resolve, 100, 'foo'); // 'foo' 传参给 resolve
});

Promise.all([promise1, promise2, promise3]).then((values) => {
  console.log(values);
});
// expected output: Array [3, 42, "foo"]
```



### Promise.allSettled()

返回一个在所有给定的promise都已经`fulfilled`或`rejected`后的promise，并带有一个对象数组，每个对象表示对应的promise结果

```js
const promise1 = Promise.resolve(3);
const promise2 = new Promise((resolve, reject) => setTimeout(reject, 100, 'foo'));
const promises = [promise1, promise2];

Promise.allSettled(promises).
  then((results) => results.forEach((result) => console.log(result.status)));

// expected output:
// "fulfilled"
// "rejected"
```



### Promise.race()

返回一个 promise，一旦迭代器中的某个promise解决或拒绝，返回的 promise就会解决或拒绝

> 看哪个任务速度快，不管是成功还是失败

```js
const promise1 = new Promise((resolve, reject) => {
  setTimeout(resolve, 500, 'one');
});

const promise2 = new Promise((resolve, reject) => {
  setTimeout(resolve, 100, 'two');
});

Promise.race([promise1, promise2]).then((value) => {
  console.log(value);
  // Both resolve, but promise2 is faster
});
// expected output: "two"
```



## async/await

### 基本用法

可以完善 .then()

> async：申明一个 function 是异步的，并且 return 返回值 会被封装成一个 Promise 对象[, await 等待时，等待 resolve 值]
>
> await：出现在 async 中，等待一个异步方法执行完成的结果

```js
function resolveAfter2Seconds() {
  return new Promise(resolve => {
    setTimeout(() => {
      resolve('resolved');
    }, 2000);
  });
}

async function asyncCall() {
  console.log('calling');
  const result = await resolveAfter2Seconds();
  console.log(result);
  // expected output: "resolved"
}

asyncCall();
```



### 解决结果为 rejected

> await 命令后面的 Promise 对象，运行结果可能是 rejected，所以可以：
>
> - 把 await 命令放在 try ... catch 代码块中
> - 增加 .catch(err => {})

```js
// try ... catch
async function myFunction() {
  try {
    await somethingThatReturnsAPromise();
  } catch (err) {
    console.log(err);
  }
}

// 另一种写法
async function myFunction() {
  await somethingThatReturnsAPromise().catch(function (err){
    console.log(err);
  });
}
```

或

```js
async function foo() {
   const p1 = new Promise((resolve) => setTimeout(() => resolve('1'), 1000))
   const p2 = new Promise((_,reject) => setTimeout(() => reject('2'), 500))
   const results = [await p1, await p2] // 不推荐使用这种方式，请使用 Promise.all或者Promise.allSettled 
}
foo().catch(() => {}) // 捕捉所有的错误... 
// p2 的返回结果不会被 await 处理
```



### 一些问题

在 arr.forEach() 中使用，因为是并发执行，所以会报错，改为继发

```js
async function dbFuc(db) {
  let docs = [{}, {}, {}];

  for (let doc of docs) {
    await db.post(doc);
  }
}
```

